Workbook

Sheet Totaux
A1: JT_CF_E10_1.6
A2: Calcul notes CFC informatique | E2: Seul les cases en bleu clair doivent être éditées
A3: Prénom Nom
A4: Moyennes globales | E4: Compétences de base élargies | S4: Culture générale
B5: Moyennes | C5: Pondérations
A6: Note finale CFC | B6: {=MROUND(SUMPRODUCT(B9:B12,C9:C12)/SUMPRODUCT(--(B9:B12<>0),C9:C12),0.1)} -> #DIV/0! | E6: Math 1 | S6: Semestre 1
P7: =IFERROR(MROUND(AVERAGEIF(E7:N7,"<>0"),0.5),0) -> 0 | R7: Langues+Société | AD7: =IFERROR(MROUND(AVERAGEIF(S7:AB7,"<>0"),0.5),0) -> 0
A8: Domaines finaux
A9: TPI | B9: 0 | C9: 0.4 | E9: Math 2 | S9: Semestre 2
A10: Compétences de base élargies | B10: =P30 -> #DIV/0! | C10: 0.1 | P10: =IFERROR(MROUND(AVERAGEIF(E10:N10,"<>0"),0.5),0) -> 0 | R10: Société | AD10: =IFERROR(MROUND(AVERAGEIF(S10:AB10,"<>0"),0.5),0) -> 0
A11: Compétences en informatique | B11: {=IFERROR(MROUND(SUMPRODUCT(B17:B18,C17:C18)/SUMPRODUCT(--(B17:B18<>0),C17:C18),0.5),0)} -> 0 | C11: 0.3
A12: Culture générale | B12: =AD36 -> #DIV/0! | C12: 0.2 | E12: Math 3 | S12: Semestre 3
P13: =IFERROR(MROUND(AVERAGEIF(E13:N13,"<>0"),0.5),0) -> 0 | R13: Société | AD13: =IFERROR(MROUND(AVERAGEIF(S13:AB13,"<>0"),0.5),0) -> 0
E15: Anglais 1 | S15: Semestre 4
P16: =IFERROR(MROUND(AVERAGEIF(E16:N16,"<>0"),0.5),0) -> 0 | R16: Société | AD16: =IFERROR(MROUND(AVERAGEIF(S16:AB16,"<>0"),0.5),0) -> 0
A17: Modules ecole pro à 0.5 | B17: =IFERROR(MROUND(AVERAGEIFS(Table1[Note],Table1[Module], "=EPSIC",Table1[Note],"<>0"),0.5),0) -> 0 | C17: 0.8
A18: Modules CIE à 0.5 | B18: =IFERROR(MROUND(AVERAGEIFS(Table1[Note],Table1[Module], "=CIE",Table1[Note],"<>0"),0.5),0) -> 0 | C18: 0.2 | E18: Anglais 2 | S18: Semestre 5
P19: =IFERROR(MROUND(AVERAGEIF(E19:N19,"<>0"),0.5),0) -> 0 | R19: Société | AD19: =IFERROR(MROUND(AVERAGEIF(S19:AB19,"<>0"),0.5),0) -> 0
E21: Anglais 3 | S21: Semestre 6
P22: =IFERROR(MROUND(AVERAGEIF(E22:N22,"<>0"),0.5),0) -> 0 | R22: Société | AD22: =IFERROR(MROUND(AVERAGEIF(S22:AB22,"<>0"),0.5),0) -> 0
E24: Anglais 4 | S24: Semestre 7
P25: =IFERROR(MROUND(AVERAGEIF(E25:N25,"<>0"),0.5),0) -> 0 | R25: Société | AD25: =IFERROR(MROUND(AVERAGEIF(S25:AB25,"<>0"),0.5),0) -> 0
E27: Anglais 5 | S27: Semestre 8
P28: =IFERROR(MROUND(AVERAGEIF(E28:N28,"<>0"),0.5),0) -> 0 | R28: Société | AD28: =IFERROR(MROUND(AVERAGEIF(S28:AB28,"<>0"),0.5),0) -> 0
N30: Moyenne 8 semestres de 40 périodes | P30: =MROUND(AVERAGEIF(P7:P28, "<>0"),0.5) -> #DIV/0!
AB31: TPA
AB33: Moyenne ECG | AD33: =MROUND(AVERAGEIF(AD7:AD29,"<>0"),0.5) -> #DIV/0! | AE33: 1
AB34: TPA | AD34: =AD31 -> 0 | AE34: 1
AB36: Moyenne culture générale | AD36: {=MROUND(SUMPRODUCT(AD33:AD34,AE33:AE34)/SUMPRODUCT(--(AD33:AD34<>0),AE33:AE34),0.5)} -> #DIV/0!

Sheet Modules informatiques
A1: No module | B1: Module | C1: Nom | D1: Note
A2: 106 | B2: CIE | C2: Interroger, traiter et assurer la maintenance des bases de données
A3: 107 | B3: CIE | C3: Mettre en oeuvre des solutions ICT avec la technologie block-chain
A4: 109 | B4: CIE | C4: Exploiter et surveiller des services dans le cloud public
A5: 110 | B5: CIE | C5: Analyser et repré-senter des données avec des outils
A6: 185 | B6: CIE | C6: Analyser et implé-menter des mesures visant à assurer la sécurité informa-tique des PME
A7: 187 | B7: CIE | C7: Mettre en service un Poste de tra-vail ICTavec le système d’exploitation
A8: 190 | B8: CIE | C8: Mettre en place et exploiter une plate-forme de virtualisa-tion
A9: 210 | B9: CIE | C9: Utiliser un cloud public pour des appli-cations
A10: 216 | B10: CIE | C10: Intégrer les ter-minaux IoE dans une plateforme existante
A11: 217 | B11: CIE | C11: Concevoir, planifier et mettre en place un service pour l’IoE
A12: 223 | B12: CIE | C12: Réaliser des applica-tions multi-utilisateurs orien-tées objets
A13: 248 | B13: CIE | C13: Réaliser des solutions ICT avec des techno-logies actuelles
... A42: 450 | B42: EPSIC | C42: Tester des applications

Sheet Sheet2
A1: Copetence pro

Sheet Projets entreprise
A1: Début | B1: Fin | C1: Identifiant | D1: Titre du projet | E1: Note obtenue
C2: E100 | D2: Evaluation, Linux et lignes de commandes
C3: B20 | D3: Static site
C4: B41 | D4: Web todo list with TypeScript
C5: B42 | D5: React todo list
C6: B44 | D6: API in TypeScript with Bun & SQLite
C7: B48 | D7: Présentation d'un langage de programmation
C8: E103 | D8: Évaluation, Programmation en JavaScript
C9: B51 | D9: PHP blog
C10: B46 | D10: Full-Stack TypeScript App
C11: E104 | D11: Évaluation, Programmation en TypeScript
C12: B52 | D12: PHP framework App
C13: B60 | D13: Working in a team - Agile and scrum
... C16: B49 | D16: Présentation d'un sujet technique en groupe

Sheet Compétences opérationelles
A1: Numéro | B1: Nom | C1: Modules EPSIC | M1: Modules CIE | U1: Moyenne | V1: Centre de formation et entreprise | AS1: Moyenne
A2: a1 | B2: Clarifier et documenter les besoins des parties prenantes dans le cadre d’un projet ICT | C2: 431 | D2: 306 | V2: B60 | W2: B70
C3: =IFERROR(VLOOKUP(C2,'Modules informatiques'!$A$2:$D$50,4,FALSE()), "") -> 0 | D3: =IFERROR(VLOOKUP(D2,'Modules informatiques'!$A$2:$D$50,4,FALSE()), "") -> 0 | E3: =IFERROR(VLOOKUP(E2,'Modules informatiques'!$A$2:$D$50,4,FALSE()), "") | F3: =IFERROR(VLOOKUP(F2,'Modules informatiques'!$A$2:$D$50,4,FALSE()), "") | G3: =IFERROR(VLOOKUP(G2,'Modules informatiques'!$A$2:$D$50,4,FALSE()), "") | H3: =IFERROR(VLOOKUP(H2,'Modules informatiques'!$A$2:$D$50,4,FALSE()), "") | I3: =IFERROR(VLOOKUP(I2,'Modules informatiques'!$A$2:$D$50,4,FALSE()), "") | J3: =IFERROR(VLOOKUP(J2,'Modules informatiques'!$A$2:$D$50,4,FALSE()), "") | ... T3: =IFERROR(VLOOKUP(T2,'Modules informatiques'!$A$2:$D$50,4,FALSE()), "") | U3: =IFERROR(AVERAGE(C3:T3), "") -> 0 | V3: =IFERROR(VLOOKUP(V2,'Projets entreprise'!$C$2:$E$91,3,FALSE()), "") -> 0 | W3: =IFERROR(VLOOKUP(W2,'Projets entreprise'!$C$2:$E$91,3,FALSE()), "") -> 0 | X3: =IFERROR(VLOOKUP(X2,'Projets entreprise'!$C$2:$E$91,3,FALSE()), "") | Y3: =IFERROR(VLOOKUP(Y2,'Projets entreprise'!$C$2:$E$91,3,FALSE()), "") | Z3: =IFERROR(VLOOKUP(Z2,'Projets entreprise'!$C$2:$E$91,3,FALSE()), "") | AA3: =IFERROR(VLOOKUP(AA2,'Projets entreprise'!$C$2:$E$91,3,FALSE()), "") | AB3: =IFERROR(VLOOKUP(AB2,'Projets entreprise'!$C$2:$E$91,3,FALSE()), "") | AC3: =IFERROR(VLOOKUP(AC2,'Projets entreprise'!$C$2:$E$91,3,FALSE()), "") | ... AR3: =IFERROR(VLOOKUP(AR2,'Projets entreprise'!$C$2:$E$91,3,FALSE()), "") | AS3: =IFERROR(AVERAGE(V3:AR3), "") -> 0
A4: a2 | B4: Définir un modèle de procédure pour un projet ICT | C4: 431 | D4: 306
C5: =IFERROR(VLOOKUP(C4,'Modules informatiques'!$A$2:$D$50,4,FALSE()), "") -> 0 | D5: =IFERROR(VLOOKUP(D4,'Modules informatiques'!$A$2:$D$50,4,FALSE()), "") -> 0 | E5: =IFERROR(VLOOKUP(E4,'Modules informatiques'!$A$2:$D$50,4,FALSE()), "") | F5: =IFERROR(VLOOKUP(F4,'Modules informatiques'!$A$2:$D$50,4,FALSE()), "") | G5: =IFERROR(VLOOKUP(G4,'Modules informatiques'!$A$2:$D$50,4,FALSE()), "") | H5: =IFERROR(VLOOKUP(H4,'Modules informatiques'!$A$2:$D$50,4,FALSE()), "") | I5: =IFERROR(VLOOKUP(I4,'Modules informatiques'!$A$2:$D$50,4,FALSE()), "") | J5: =IFERROR(VLOOKUP(J4,'Modules informatiques'!$A$2:$D$50,4,FALSE()), "") | ... T5: =IFERROR(VLOOKUP(T4,'Modules informatiques'!$A$2:$D$50,4,FALSE()), "") | U5: =IFERROR(AVERAGE(C5:T5), "") -> 0 | V5: =IFERROR(VLOOKUP(V4,'Projets entreprise'!$C$2:$E$91,3,FALSE()), "") | W5: =IFERROR(VLOOKUP(W4,'Projets entreprise'!$C$2:$E$91,3,FALSE()), "") | X5: =IFERROR(VLOOKUP(X4,'Projets entreprise'!$C$2:$E$91,3,FALSE()), "") | Y5: =IFERROR(VLOOKUP(Y4,'Projets entreprise'!$C$2:$E$91,3,FALSE()), "") | Z5: =IFERROR(VLOOKUP(Z4,'Projets entreprise'!$C$2:$E$91,3,FALSE()), "") | AA5: =IFERROR(VLOOKUP(AA4,'Projets entreprise'!$C$2:$E$91,3,FALSE()), "") | AB5: =IFERROR(VLOOKUP(AB4,'Projets entreprise'!$C$2:$E$91,3,FALSE()), "") | AC5: =IFERROR(VLOOKUP(AC4,'Projets entreprise'!$C$2:$E$91,3,FALSE()), "") | ... AR5: =IFERROR(VLOOKUP(AR4,'Projets entreprise'!$C$2:$E$91,3,FALSE()), "") | AS5: =IFERROR(AVERAGE(V5:AR5), "")
A6: a3 | B6: Rechercher des informations sur des solutions ICT et sur les innovations | C6: 241 | D6: 245 | M6: 248 | V6: B20 | W6: B41 | X6: B42 | Y6: B48 | Z6: B49
C7: =IFERROR(VLOOKUP(C6,'Modules informatiques'!$A$2:$D$50,4,FALSE()), "") -> 0 | D7: =IFERROR(VLOOKUP(D6,'Modules informatiques'!$A$2:$D$50,4,FALSE()), "") -> 0 | E7: =IFERROR(VLOOKUP(E6,'Modules informatiques'!$A$2:$D$50,4,FALSE()), "") | F7: =IFERROR(VLOOKUP(F6,'Modules informatiques'!$A$2:$D$50,4,FALSE()), "") | G7: =IFERROR(VLOOKUP(G6,'Modules informatiques'!$A$2:$D$50,4,FALSE()), "") | H7: =IFERROR(VLOOKUP(H6,'Modules informatiques'!$A$2:$D$50,4,FALSE()), "") | I7: =IFERROR(VLOOKUP(I6,'Modules informatiques'!$A$2:$D$50,4,FALSE()), "") | J7: =IFERROR(VLOOKUP(J6,'Modules informatiques'!$A$2:$D$50,4,FALSE()), "") | ... T7: =IFERROR(VLOOKUP(T6,'Modules informatiques'!$A$2:$D$50,4,FALSE()), "") | U7: =IFERROR(AVERAGE(C7:T7), "") -> 0 | V7: =IFERROR(VLOOKUP(V6,'Projets entreprise'!$C$2:$E$91,3,FALSE()), "") -> 0 | W7: =IFERROR(VLOOKUP(W6,'Projets entreprise'!$C$2:$E$91,3,FALSE()), "") -> 0 | X7: =IFERROR(VLOOKUP(X6,'Projets entreprise'!$C$2:$E$91,3,FALSE()), "") -> 0 | Y7: =IFERROR(VLOOKUP(Y6,'Projets entreprise'!$C$2:$E$91,3,FALSE()), "") -> 0 | Z7: =IFERROR(VLOOKUP(Z6,'Projets entreprise'!$C$2:$E$91,3,FALSE()), "") -> 0 | AA7: =IFERROR(VLOOKUP(AA6,'Projets entreprise'!$C$2:$E$91,3,FALSE()), "") | AB7: =IFERROR(VLOOKUP(AB6,'Projets entreprise'!$C$2:$E$91,3,FALSE()), "") | AC7: =IFERROR(VLOOKUP(AC6,'Projets entreprise'!$C$2:$E$91,3,FALSE()), "") | ... AR7: =IFERROR(VLOOKUP(AR6,'Projets entreprise'!$C$2:$E$91,3,FALSE()), "") | AS7: =IFERROR(AVERAGE(V7:AR7), "") -> 0
A8: a4 | B8: Planifier les projets ICT et les tâches selon un modèle de procédure | C8: 431 | D8: 306 | V8: B44 | W8: B48 | X8: B42 | Y8: B51 | Z8: B46 | AA8: B52 | AB8: B60 | AC8: B70 | AD8: B49
C9: =IFERROR(VLOOKUP(C8,'Modules informatiques'!$A$2:$D$50,4,FALSE()), "") -> 0 | D9: =IFERROR(VLOOKUP(D8,'Modules informatiques'!$A$2:$D$50,4,FALSE()), "") -> 0 | E9: =IFERROR(VLOOKUP(E8,'Modules informatiques'!$A$2:$D$50,4,FALSE()), "") | F9: =IFERROR(VLOOKUP(F8,'Modules informatiques'!$A$2:$D$50,4,FALSE()), "") | G9: =IFERROR(VLOOKUP(G8,'Modules informatiques'!$A$2:$D$50,4,FALSE()), "") | H9: =IFERROR(VLOOKUP(H8,'Modules informatiques'!$A$2:$D$50,4,FALSE()), "") | I9: =IFERROR(VLOOKUP(I8,'Modules informatiques'!$A$2:$D$50,4,FALSE()), "") | J9: =IFERROR(VLOOKUP(J8,'Modules informatiques'!$A$2:$D$50,4,FALSE()), "") | ... T9: =IFERROR(VLOOKUP(T8,'Modules informatiques'!$A$2:$D$50,4,FALSE()), "") | U9: =IFERROR(AVERAGE(C9:T9), "") -> 0 | V9: =IFERROR(VLOOKUP(V8,'Projets entreprise'!$C$2:$E$91,3,FALSE()), "") -> 0 | W9: =IFERROR(VLOOKUP(W8,'Projets entreprise'!$C$2:$E$91,3,FALSE()), "") -> 0 | X9: =IFERROR(VLOOKUP(X8,'Projets entreprise'!$C$2:$E$91,3,FALSE()), "") -> 0 | Y9: =IFERROR(VLOOKUP(Y8,'Projets entreprise'!$C$2:$E$91,3,FALSE()), "") -> 0 | Z9: =IFERROR(VLOOKUP(Z8,'Projets entreprise'!$C$2:$E$91,3,FALSE()), "") -> 0 | AA9: =IFERROR(VLOOKUP(AA8,'Projets entreprise'!$C$2:$E$91,3,FALSE()), "") -> 0 | AB9: =IFERROR(VLOOKUP(AB8,'Projets entreprise'!$C$2:$E$91,3,FALSE()), "") -> 0 | AC9: =IFERROR(VLOOKUP(AC8,'Projets entreprise'!$C$2:$E$91,3,FALSE()), "") -> 0 | ... AR9: =IFERROR(VLOOKUP(AR8,'Projets entreprise'!$C$2:$E$91,3,FALSE()), "") | AS9: =IFERROR(AVERAGE(V9:AR9), "") -> 0
A10: a5 | B10: Visualiser et présenter les variantes de solutions ICT | C10: 431 | D10: 306 | V10: B48 | W10: B60 | X10: B49
C11: =IFERROR(VLOOKUP(C10,'Modules informatiques'!$A$2:$D$50,4,FALSE()), "") -> 0 | D11: =IFERROR(VLOOKUP(D10,'Modules informatiques'!$A$2:$D$50,4,FALSE()), "") -> 0 | E11: =IFERROR(VLOOKUP(E10,'Modules informatiques'!$A$2:$D$50,4,FALSE()), "") | F11: =IFERROR(VLOOKUP(F10,'Modules informatiques'!$A$2:$D$50,4,FALSE()), "") | G11: =IFERROR(VLOOKUP(G10,'Modules informatiques'!$A$2:$D$50,4,FALSE()), "") | H11: =IFERROR(VLOOKUP(H10,'Modules informatiques'!$A$2:$D$50,4,FALSE()), "") | I11: =IFERROR(VLOOKUP(I10,'Modules informatiques'!$A$2:$D$50,4,FALSE()), "") | J11: =IFERROR(VLOOKUP(J10,'Modules informatiques'!$A$2:$D$50,4,FALSE()), "") | ... T11: =IFERROR(VLOOKUP(T10,'Modules informatiques'!$A$2:$D$50,4,FALSE()), "") | U11: =IFERROR(AVERAGE(C11:T11), "") -> 0 | V11: =IFERROR(VLOOKUP(V10,'Projets entreprise'!$C$2:$E$91,3,FALSE()), "") -> 0 | W11: =IFERROR(VLOOKUP(W10,'Projets entreprise'!$C$2:$E$91,3,FALSE()), "") -> 0 | X11: =IFERROR(VLOOKUP(X10,'Projets entreprise'!$C$2:$E$91,3,FALSE()), "") -> 0 | Y11: =IFERROR(VLOOKUP(Y10,'Projets entreprise'!$C$2:$E$91,3,FALSE()), "") | Z11: =IFERROR(VLOOKUP(Z10,'Projets entreprise'!$C$2:$E$91,3,FALSE()), "") | AA11: =IFERROR(VLOOKUP(AA10,'Projets entreprise'!$C$2:$E$91,3,FALSE()), "") | AB11: =IFERROR(VLOOKUP(AB10,'Projets entreprise'!$C$2:$E$91,3,FALSE()), "") | AC11: =IFERROR(VLOOKUP(AC10,'Projets entreprise'!$C$2:$E$91,3,FALSE()), "") | ... AR11: =IFERROR(VLOOKUP(AR10,'Projets entreprise'!$C$2:$E$91,3,FALSE()), "") | AS11: =IFERROR(AVERAGE(V11:AR11), "") -> 0
A12: a6 | B12: Vérifier l’avancement des projets ICT et des tâches et en faire état selon le modèle de procédure | C12: 431 | D12: 306 | V12: B20 | W12: B41 | X12: B42 | Y12: B44 | Z12: B51 | AA12: B46 | AB12: B60 | AC12: B70
C13: =IFERROR(VLOOKUP(C12,'Modules informatiques'!$A$2:$D$50,4,FALSE()), "") -> 0 | D13: =IFERROR(VLOOKUP(D12,'Modules informatiques'!$A$2:$D$50,4,FALSE()), "") -> 0 | E13: =IFERROR(VLOOKUP(E12,'Modules informatiques'!$A$2:$D$50,4,FALSE()), "") | F13: =IFERROR(VLOOKUP(F12,'Modules informatiques'!$A$2:$D$50,4,FALSE()), "") | G13: =IFERROR(VLOOKUP(G12,'Modules informatiques'!$A$2:$D$50,4,FALSE()), "") | H13: =IFERROR(VLOOKUP(H12,'Modules informatiques'!$A$2:$D$50,4,FALSE()), "") | I13: =IFERROR(VLOOKUP(I12,'Modules informatiques'!$A$2:$D$50,4,FALSE()), "") | J13: =IFERROR(VLOOKUP(J12,'Modules informatiques'!$A$2:$D$50,4,FALSE()), "") | ... T13: =IFERROR(VLOOKUP(T12,'Modules informatiques'!$A$2:$D$50,4,FALSE()), "") | U13: =IFERROR(AVERAGE(C13:T13), "") -> 0 | V13: =IFERROR(VLOOKUP(V12,'Projets entreprise'!$C$2:$E$91,3,FALSE()), "") -> 0 | W13: =IFERROR(VLOOKUP(W12,'Projets entreprise'!$C$2:$E$91,3,FALSE()), "") -> 0 | X13: =IFERROR(VLOOKUP(X12,'Projets entreprise'!$C$2:$E$91,3,FALSE()), "") -> 0 | Y13: =IFERROR(VLOOKUP(Y12,'Projets entreprise'!$C$2:$E$91,3,FALSE()), "") -> 0 | Z13: =IFERROR(VLOOKUP(Z12,'Projets entreprise'!$C$2:$E$91,3,FALSE()), "") -> 0 | AA13: =IFERROR(VLOOKUP(AA12,'Projets entreprise'!$C$2:$E$91,3,FALSE()), "") -> 0 | AB13: =IFERROR(VLOOKUP(AB12,'Projets entreprise'!$C$2:$E$91,3,FALSE()), "") -> 0 | AC13: =IFERROR(VLOOKUP(AC12,'Projets entreprise'!$C$2:$E$91,3,FALSE()), "") -> 0 | ... AR13: =IFERROR(VLOOKUP(AR12,'Projets entreprise'!$C$2:$E$91,3,FALSE()), "") | AS13: =IFERROR(AVERAGE(V13:AR13), "") -> 0
A14: a7 | B14: Remettre la solution ICT au client et clôturer le projet | C14: 431 | D14: 306 | V14: B20 | W14: B41 | X14: B51 | Y14: B60
C15: =IFERROR(VLOOKUP(C14,'Modules informatiques'!$A$2:$D$50,4,FALSE()), "") -> 0 | D15: =IFERROR(VLOOKUP(D14,'Modules informatiques'!$A$2:$D$50,4,FALSE()), "") -> 0 | E15: =IFERROR(VLOOKUP(E14,'Modules informatiques'!$A$2:$D$50,4,FALSE()), "") | F15: =IFERROR(VLOOKUP(F14,'Modules informatiques'!$A$2:$D$50,4,FALSE()), "") | G15: =IFERROR(VLOOKUP(G14,'Modules informatiques'!$A$2:$D$50,4,FALSE()), "") | H15: =IFERROR(VLOOKUP(H14,'Modules informatiques'!$A$2:$D$50,4,FALSE()), "") | I15: =IFERROR(VLOOKUP(I14,'Modules informatiques'!$A$2:$D$50,4,FALSE()), "") | J15: =IFERROR(VLOOKUP(J14,'Modules informatiques'!$A$2:$D$50,4,FALSE()), "") | ... T15: =IFERROR(VLOOKUP(T14,'Modules informatiques'!$A$2:$D$50,4,FALSE()), "") | U15: =IFERROR(AVERAGE(C15:T15), "") -> 0 | V15: =IFERROR(VLOOKUP(V14,'Projets entreprise'!$C$2:$E$91,3,FALSE()), "") -> 0 | W15: =IFERROR(VLOOKUP(W14,'Projets entreprise'!$C$2:$E$91,3,FALSE()), "") -> 0 | X15: =IFERROR(VLOOKUP(X14,'Projets entreprise'!$C$2:$E$91,3,FALSE()), "") -> 0 | Y15: =IFERROR(VLOOKUP(Y14,'Projets entreprise'!$C$2:$E$91,3,FALSE()), "") -> 0 | Z15: =IFERROR(VLOOKUP(Z14,'Projets entreprise'!$C$2:$E$91,3,FALSE()), "") | AA15: =IFERROR(VLOOKUP(AA14,'Projets entreprise'!$C$2:$E$91,3,FALSE()), "") | AB15: =IFERROR(VLOOKUP(AB14,'Projets entreprise'!$C$2:$E$91,3,FALSE()), "") | AC15: =IFERROR(VLOOKUP(AC14,'Projets entreprise'!$C$2:$E$91,3,FALSE()), "") | ... AR15: =IFERROR(VLOOKUP(AR14,'Projets entreprise'!$C$2:$E$91,3,FALSE()), "") | AS15: =IFERROR(AVERAGE(V15:AR15), "") -> 0
A16: b1 | B16: Installer un PC monoposte | C16: 114 | D16: 117 | M16: 187 | V16: E100
C17: =IFERROR(VLOOKUP(C16,'Modules informatiques'!$A$2:$D$50,4,FALSE()), "") -> 0 | D17: =IFERROR(VLOOKUP(D16,'Modules informatiques'!$A$2:$D$50,4,FALSE()), "") -> 0 | E17: =IFERROR(VLOOKUP(E16,'Modules informatiques'!$A$2:$D$50,4,FALSE()), "") | F17: =IFERROR(VLOOKUP(F16,'Modules informatiques'!$A$2:$D$50,4,FALSE()), "") | G17: =IFERROR(VLOOKUP(G16,'Modules informatiques'!$A$2:$D$50,4,FALSE()), "") | H17: =IFERROR(VLOOKUP(H16,'Modules informatiques'!$A$2:$D$50,4,FALSE()), "") | I17: =IFERROR(VLOOKUP(I16,'Modules informatiques'!$A$2:$D$50,4,FALSE()), "") | J17: =IFERROR(VLOOKUP(J16,'Modules informatiques'!$A$2:$D$50,4,FALSE()), "") | ... T17: =IFERROR(VLOOKUP(T16,'Modules informatiques'!$A$2:$D$50,4,FALSE()), "") | U17: =IFERROR(AVERAGE(C17:T17), "") -> 0 | V17: =IFERROR(VLOOKUP(V16,'Projets entreprise'!$C$2:$E$91,3,FALSE()), "") -> 0 | W17: =IFERROR(VLOOKUP(W16,'Projets entreprise'!$C$2:$E$91,3,FALSE()), "") | X17: =IFERROR(VLOOKUP(X16,'Projets entreprise'!$C$2:$E$91,3,FALSE()), "") | Y17: =IFERROR(VLOOKUP(Y16,'Projets entreprise'!$C$2:$E$91,3,FALSE()), "") | Z17: =IFERROR(VLOOKUP(Z16,'Projets entreprise'!$C$2:$E$91,3,FALSE()), "") | AA17: =IFERROR(VLOOKUP(AA16,'Projets entreprise'!$C$2:$E$91,3,FALSE()), "") | AB17: =IFERROR(VLOOKUP(AB16,'Projets entreprise'!$C$2:$E$91,3,FALSE()), "") | AC17: =IFERROR(VLOOKUP(AC16,'Projets entreprise'!$C$2:$E$91,3,FALSE()), "") | ... AR17: =IFERROR(VLOOKUP(AR16,'Projets entreprise'!$C$2:$E$91,3,FALSE()), "") | AS17: =IFERROR(AVERAGE(V17:AR17), "") -> 0
A18: b2 | B18: Réceptionner et traiter des demandes d’assistance informatique complexes
C19: =IFERROR(VLOOKUP(C18,'Modules informatiques'!$A$2:$D$50,4,FALSE()), "") | D19: =IFERROR(VLOOKUP(D18,'Modules informatiques'!$A$2:$D$50,4,FALSE()), "") | E19: =IFERROR(VLOOKUP(E18,'Modules informatiques'!$A$2:$D$50,4,FALSE()), "") | F19: =IFERROR(VLOOKUP(F18,'Modules informatiques'!$A$2:$D$50,4,FALSE()), "") | G19: =IFERROR(VLOOKUP(G18,'Modules informatiques'!$A$2:$D$50,4,FALSE()), "") | H19: =IFERROR(VLOOKUP(H18,'Modules informatiques'!$A$2:$D$50,4,FALSE()), "") | I19: =IFERROR(VLOOKUP(I18,'Modules informatiques'!$A$2:$D$50,4,FALSE()), "") | J19: =IFERROR(VLOOKUP(J18,'Modules informatiques'!$A$2:$D$50,4,FALSE()), "") | ... T19: =IFERROR(VLOOKUP(T18,'Modules informatiques'!$A$2:$D$50,4,FALSE()), "") | U19: =IFERROR(AVERAGE(C19:T19), "") | V19: =IFERROR(VLOOKUP(V18,'Projets entreprise'!$C$2:$E$91,3,FALSE()), "") | W19: =IFERROR(VLOOKUP(W18,'Projets entreprise'!$C$2:$E$91,3,FALSE()), "") | X19: =IFERROR(VLOOKUP(X18,'Projets entreprise'!$C$2:$E$91,3,FALSE()), "") | Y19: =IFERROR(VLOOKUP(Y18,'Projets entreprise'!$C$2:$E$91,3,FALSE()), "") | Z19: =IFERROR(VLOOKUP(Z18,'Projets entreprise'!$C$2:$E$91,3,FALSE()), "") | AA19: =IFERROR(VLOOKUP(AA18,'Projets entreprise'!$C$2:$E$91,3,FALSE()), "") | AB19: =IFERROR(VLOOKUP(AB18,'Projets entreprise'!$C$2:$E$91,3,FALSE()), "") | AC19: =IFERROR(VLOOKUP(AC18,'Projets entreprise'!$C$2:$E$91,3,FALSE()), "") | ... AR19: =IFERROR(VLOOKUP(AR18,'Projets entreprise'!$C$2:$E$91,3,FALSE()), "") | AS19: =IFERROR(AVERAGE(V19:AR19), "")
A20: b3 | B20: Conseiller les clients en matière de protection et de sécurité des données | C20: 231 | M20: 216 | N20: 217 | O20: 185 | P20: 107
C21: =IFERROR(VLOOKUP(C20,'Modules informatiques'!$A$2:$D$50,4,FALSE()), "") -> 0 | D21: =IFERROR(VLOOKUP(D20,'Modules informatiques'!$A$2:$D$50,4,FALSE()), "") | E21: =IFERROR(VLOOKUP(E20,'Modules informatiques'!$A$2:$D$50,4,FALSE()), "") | F21: =IFERROR(VLOOKUP(F20,'Modules informatiques'!$A$2:$D$50,4,FALSE()), "") | G21: =IFERROR(VLOOKUP(G20,'Modules informatiques'!$A$2:$D$50,4,FALSE()), "") | H21: =IFERROR(VLOOKUP(H20,'Modules informatiques'!$A$2:$D$50,4,FALSE()), "") | I21: =IFERROR(VLOOKUP(I20,'Modules informatiques'!$A$2:$D$50,4,FALSE()), "") | J21: =IFERROR(VLOOKUP(J20,'Modules informatiques'!$A$2:$D$50,4,FALSE()), "") | ... T21: =IFERROR(VLOOKUP(T20,'Modules informatiques'!$A$2:$D$50,4,FALSE()), "") | U21: =IFERROR(AVERAGE(C21:T21), "") -> 0 | V21: =IFERROR(VLOOKUP(V20,'Projets entreprise'!$C$2:$E$91,3,FALSE()), "") | W21: =IFERROR(VLOOKUP(W20,'Projets entreprise'!$C$2:$E$91,3,FALSE()), "") | X21: =IFERROR(VLOOKUP(X20,'Projets entreprise'!$C$2:$E$91,3,FALSE()), "") | Y21: =IFERROR(VLOOKUP(Y20,'Projets entreprise'!$C$2:$E$91,3,FALSE()), "") | Z21: =IFERROR(VLOOKUP(Z20,'Projets entreprise'!$C$2:$E$91,3,FALSE()), "") | AA21: =IFERROR(VLOOKUP(AA20,'Projets entreprise'!$C$2:$E$91,3,FALSE()), "") | AB21: =IFERROR(VLOOKUP(AB20,'Projets entreprise'!$C$2:$E$91,3,FALSE()), "") | AC21: =IFERROR(VLOOKUP(AC20,'Projets entreprise'!$C$2:$E$91,3,FALSE()), "") | ... AR21: =IFERROR(VLOOKUP(AR20,'Projets entreprise'!$C$2:$E$91,3,FALSE()), "") | AS21: =IFERROR(AVERAGE(V21:AR21), "")
A22: b4 | B22: Analyser, visualiser et documenter les processus métier des clients | C22: 254 | V22: B60 | W22: B49
C23: =IFERROR(VLOOKUP(C22,'Modules informatiques'!$A$2:$D$50,4,FALSE()), "") -> 0 | D23: =IFERROR(VLOOKUP(D22,'Modules informatiques'!$A$2:$D$50,4,FALSE()), "") | E23: =IFERROR(VLOOKUP(E22,'Modules informatiques'!$A$2:$D$50,4,FALSE()), "") | F23: =IFERROR(VLOOKUP(F22,'Modules informatiques'!$A$2:$D$50,4,FALSE()), "") | G23: =IFERROR(VLOOKUP(G22,'Modules informatiques'!$A$2:$D$50,4,FALSE()), "") | H23: =IFERROR(VLOOKUP(H22,'Modules informatiques'!$A$2:$D$50,4,FALSE()), "") | I23: =IFERROR(VLOOKUP(I22,'Modules informatiques'!$A$2:$D$50,4,FALSE()), "") | J23: =IFERROR(VLOOKUP(J22,'Modules informatiques'!$A$2:$D$50,4,FALSE()), "") | ... T23: =IFERROR(VLOOKUP(T22,'Modules informatiques'!$A$2:$D$50,4,FALSE()), "") | U23: =IFERROR(AVERAGE(C23:T23), "") -> 0 | V23: =IFERROR(VLOOKUP(V22,'Projets entreprise'!$C$2:$E$91,3,FALSE()), "") -> 0 | W23: =IFERROR(VLOOKUP(W22,'Projets entreprise'!$C$2:$E$91,3,FALSE()), "") -> 0 | X23: =IFERROR(VLOOKUP(X22,'Projets entreprise'!$C$2:$E$91,3,FALSE()), "") | Y23: =IFERROR(VLOOKUP(Y22,'Projets entreprise'!$C$2:$E$91,3,FALSE()), "") | Z23: =IFERROR(VLOOKUP(Z22,'Projets entreprise'!$C$2:$E$91,3,FALSE()), "") | AA23: =IFERROR(VLOOKUP(AA22,'Projets entreprise'!$C$2:$E$91,3,FALSE()), "") | AB23: =IFERROR(VLOOKUP(AB22,'Projets entreprise'!$C$2:$E$91,3,FALSE()), "") | AC23: =IFERROR(VLOOKUP(AC22,'Projets entreprise'!$C$2:$E$91,3,FALSE()), "") | ... AR23: =IFERROR(VLOOKUP(AR22,'Projets entreprise'!$C$2:$E$91,3,FALSE()), "") | AS23: =IFERROR(AVERAGE(V23:AR23), "") -> 0
A24: c1 | B24: Identifier et analyser les données et développer des modèles de données | C24: 162 | D24: 164 | M24: 110 | N24: 259 | V24: B52
C25: =IFERROR(VLOOKUP(C24,'Modules informatiques'!$A$2:$D$50,4,FALSE()), "") -> 0 | D25: =IFERROR(VLOOKUP(D24,'Modules informatiques'!$A$2:$D$50,4,FALSE()), "") -> 0 | E25: =IFERROR(VLOOKUP(E24,'Modules informatiques'!$A$2:$D$50,4,FALSE()), "") | F25: =IFERROR(VLOOKUP(F24,'Modules informatiques'!$A$2:$D$50,4,FALSE()), "") | G25: =IFERROR(VLOOKUP(G24,'Modules informatiques'!$A$2:$D$50,4,FALSE()), "") | H25: =IFERROR(VLOOKUP(H24,'Modules informatiques'!$A$2:$D$50,4,FALSE()), "") | I25: =IFERROR(VLOOKUP(I24,'Modules informatiques'!$A$2:$D$50,4,FALSE()), "") | J25: =IFERROR(VLOOKUP(J24,'Modules informatiques'!$A$2:$D$50,4,FALSE()), "") | ... T25: =IFERROR(VLOOKUP(T24,'Modules informatiques'!$A$2:$D$50,4,FALSE()), "") | U25: =IFERROR(AVERAGE(C25:T25), "") -> 0 | V25: =IFERROR(VLOOKUP(V24,'Projets entreprise'!$C$2:$E$91,3,FALSE()), "") -> 0 | W25: =IFERROR(VLOOKUP(W24,'Projets entreprise'!$C$2:$E$91,3,FALSE()), "") | X25: =IFERROR(VLOOKUP(X24,'Projets entreprise'!$C$2:$E$91,3,FALSE()), "") | Y25: =IFERROR(VLOOKUP(Y24,'Projets entreprise'!$C$2:$E$91,3,FALSE()), "") | Z25: =IFERROR(VLOOKUP(Z24,'Projets entreprise'!$C$2:$E$91,3,FALSE()), "") | AA25: =IFERROR(VLOOKUP(AA24,'Projets entreprise'!$C$2:$E$91,3,FALSE()), "") | AB25: =IFERROR(VLOOKUP(AB24,'Projets entreprise'!$C$2:$E$91,3,FALSE()), "") | AC25: =IFERROR(VLOOKUP(AC24,'Projets entreprise'!$C$2:$E$91,3,FALSE()), "") | ... AR25: =IFERROR(VLOOKUP(AR24,'Projets entreprise'!$C$2:$E$91,3,FALSE()), "") | AS25: =IFERROR(AVERAGE(V25:AR25), "") -> 0
A26: c2 | B26: Mettre en œuvre des modèles de données dans un dispositif de stockage de données numériques | C26: 164 | M26: 106 | V26: B44 | W26: B51 | X26: B46 | Y26: B52 | Z26: B60
C27: =IFERROR(VLOOKUP(C26,'Modules informatiques'!$A$2:$D$50,4,FALSE()), "") -> 0 | D27: =IFERROR(VLOOKUP(D26,'Modules informatiques'!$A$2:$D$50,4,FALSE()), "") | E27: =IFERROR(VLOOKUP(E26,'Modules informatiques'!$A$2:$D$50,4,FALSE()), "") | F27: =IFERROR(VLOOKUP(F26,'Modules informatiques'!$A$2:$D$50,4,FALSE()), "") | G27: =IFERROR(VLOOKUP(G26,'Modules informatiques'!$A$2:$D$50,4,FALSE()), "") | H27: =IFERROR(VLOOKUP(H26,'Modules informatiques'!$A$2:$D$50,4,FALSE()), "") | I27: =IFERROR(VLOOKUP(I26,'Modules informatiques'!$A$2:$D$50,4,FALSE()), "") | J27: =IFERROR(VLOOKUP(J26,'Modules informatiques'!$A$2:$D$50,4,FALSE()), "") | ... T27: =IFERROR(VLOOKUP(T26,'Modules informatiques'!$A$2:$D$50,4,FALSE()), "") | U27: =IFERROR(AVERAGE(C27:T27), "") -> 0 | V27: =IFERROR(VLOOKUP(V26,'Projets entreprise'!$C$2:$E$91,3,FALSE()), "") -> 0 | W27: =IFERROR(VLOOKUP(W26,'Projets entreprise'!$C$2:$E$91,3,FALSE()), "") -> 0 | X27: =IFERROR(VLOOKUP(X26,'Projets entreprise'!$C$2:$E$91,3,FALSE()), "") -> 0 | Y27: =IFERROR(VLOOKUP(Y26,'Projets entreprise'!$C$2:$E$91,3,FALSE()), "") -> 0 | Z27: =IFERROR(VLOOKUP(Z26,'Projets entreprise'!$C$2:$E$91,3,FALSE()), "") -> 0 | AA27: =IFERROR(VLOOKUP(AA26,'Projets entreprise'!$C$2:$E$91,3,FALSE()), "") | AB27: =IFERROR(VLOOKUP(AB26,'Projets entreprise'!$C$2:$E$91,3,FALSE()), "") | AC27: =IFERROR(VLOOKUP(AC26,'Projets entreprise'!$C$2:$E$91,3,FALSE()), "") | ... AR27: =IFERROR(VLOOKUP(AR26,'Projets entreprise'!$C$2:$E$91,3,FALSE()), "") | AS27: =IFERROR(AVERAGE(V27:AR27), "") -> 0
A28: c3 | B28: Planifier, implémenter et documenter la sécurité et la protection des données pour des solutions ICT | C28: 231 | M28: 106 | N28: 185 | O28: 210 | P28: 109 | Q28: 107 | R28: 159 | V28: B51
C29: =IFERROR(VLOOKUP(C28,'Modules informatiques'!$A$2:$D$50,4,FALSE()), "") -> 0 | D29: =IFERROR(VLOOKUP(D28,'Modules informatiques'!$A$2:$D$50,4,FALSE()), "") | E29: =IFERROR(VLOOKUP(E28,'Modules informatiques'!$A$2:$D$50,4,FALSE()), "") | F29: =IFERROR(VLOOKUP(F28,'Modules informatiques'!$A$2:$D$50,4,FALSE()), "") | G29: =IFERROR(VLOOKUP(G28,'Modules informatiques'!$A$2:$D$50,4,FALSE()), "") | H29: =IFERROR(VLOOKUP(H28,'Modules informatiques'!$A$2:$D$50,4,FALSE()), "") | I29: =IFERROR(VLOOKUP(I28,'Modules informatiques'!$A$2:$D$50,4,FALSE()), "") | J29: =IFERROR(VLOOKUP(J28,'Modules informatiques'!$A$2:$D$50,4,FALSE()), "") | ... T29: =IFERROR(VLOOKUP(T28,'Modules informatiques'!$A$2:$D$50,4,FALSE()), "") | U29: =IFERROR(AVERAGE(C29:T29), "") -> 0 | V29: =IFERROR(VLOOKUP(V28,'Projets entreprise'!$C$2:$E$91,3,FALSE()), "") -> 0 | W29: =IFERROR(VLOOKUP(W28,'Projets entreprise'!$C$2:$E$91,3,FALSE()), "") | X29: =IFERROR(VLOOKUP(X28,'Projets entreprise'!$C$2:$E$91,3,FALSE()), "") | Y29: =IFERROR(VLOOKUP(Y28,'Projets entreprise'!$C$2:$E$91,3,FALSE()), "") | Z29: =IFERROR(VLOOKUP(Z28,'Projets entreprise'!$C$2:$E$91,3,FALSE()), "") | AA29: =IFERROR(VLOOKUP(AA28,'Projets entreprise'!$C$2:$E$91,3,FALSE()), "") | AB29: =IFERROR(VLOOKUP(AB28,'Projets entreprise'!$C$2:$E$91,3,FALSE()), "") | AC29: =IFERROR(VLOOKUP(AC28,'Projets entreprise'!$C$2:$E$91,3,FALSE()), "") | ... AR29: =IFERROR(VLOOKUP(AR28,'Projets entreprise'!$C$2:$E$91,3,FALSE()), "") | AS29: =IFERROR(AVERAGE(V29:AR29), "") -> 0
A30: c4 | B30: Traiter des données à partir de dispositifs de stockage de données numériques | C30: 162 | M30: 259 | N30: 110
C31: =IFERROR(VLOOKUP(C30,'Modules informatiques'!$A$2:$D$50,4,FALSE()), "") -> 0 | D31: =IFERROR(VLOOKUP(D30,'Modules informatiques'!$A$2:$D$50,4,FALSE()), "") | E31: =IFERROR(VLOOKUP(E30,'Modules informatiques'!$A$2:$D$50,4,FALSE()), "") | F31: =IFERROR(VLOOKUP(F30,'Modules informatiques'!$A$2:$D$50,4,FALSE()), "") | G31: =IFERROR(VLOOKUP(G30,'Modules informatiques'!$A$2:$D$50,4,FALSE()), "") | H31: =IFERROR(VLOOKUP(H30,'Modules informatiques'!$A$2:$D$50,4,FALSE()), "") | I31: =IFERROR(VLOOKUP(I30,'Modules informatiques'!$A$2:$D$50,4,FALSE()), "") | J31: =IFERROR(VLOOKUP(J30,'Modules informatiques'!$A$2:$D$50,4,FALSE()), "") | ... T31: =IFERROR(VLOOKUP(T30,'Modules informatiques'!$A$2:$D$50,4,FALSE()), "") | U31: =IFERROR(AVERAGE(C31:T31), "") -> 0 | V31: =IFERROR(VLOOKUP(V30,'Projets entreprise'!$C$2:$E$91,3,FALSE()), "") | W31: =IFERROR(VLOOKUP(W30,'Projets entreprise'!$C$2:$E$91,3,FALSE()), "") | X31: =IFERROR(VLOOKUP(X30,'Projets entreprise'!$C$2:$E$91,3,FALSE()), "") | Y31: =IFERROR(VLOOKUP(Y30,'Projets entreprise'!$C$2:$E$91,3,FALSE()), "") | Z31: =IFERROR(VLOOKUP(Z30,'Projets entreprise'!$C$2:$E$91,3,FALSE()), "") | AA31: =IFERROR(VLOOKUP(AA30,'Projets entreprise'!$C$2:$E$91,3,FALSE()), "") | AB31: =IFERROR(VLOOKUP(AB30,'Projets entreprise'!$C$2:$E$91,3,FALSE()), "") | AC31: =IFERROR(VLOOKUP(AC30,'Projets entreprise'!$C$2:$E$91,3,FALSE()), "") | ... AR31: =IFERROR(VLOOKUP(AR30,'Projets entreprise'!$C$2:$E$91,3,FALSE()), "") | AS31: =IFERROR(AVERAGE(V31:AR31), "")
A32: g1 | B32: Analyser et documenter les besoins en matière d’applications et d’interfaces | C32: 332 | D32: 254 | E32: 426 | F32: 162 | G32: 164 | H32: 321 | I32: 346 | J32: 324 | V32: B44 | W32: B60
C33: =IFERROR(VLOOKUP(C32,'Modules informatiques'!$A$2:$D$50,4,FALSE()), "") -> 0 | D33: =IFERROR(VLOOKUP(D32,'Modules informatiques'!$A$2:$D$50,4,FALSE()), "") -> 0 | E33: =IFERROR(VLOOKUP(E32,'Modules informatiques'!$A$2:$D$50,4,FALSE()), "") -> 0 | F33: =IFERROR(VLOOKUP(F32,'Modules informatiques'!$A$2:$D$50,4,FALSE()), "") -> 0 | G33: =IFERROR(VLOOKUP(G32,'Modules informatiques'!$A$2:$D$50,4,FALSE()), "") -> 0 | H33: =IFERROR(VLOOKUP(H32,'Modules informatiques'!$A$2:$D$50,4,FALSE()), "") -> 0 | I33: =IFERROR(VLOOKUP(I32,'Modules informatiques'!$A$2:$D$50,4,FALSE()), "") -> 0 | J33: =IFERROR(VLOOKUP(J32,'Modules informatiques'!$A$2:$D$50,4,FALSE()), "") -> 0 | ... T33: =IFERROR(VLOOKUP(T32,'Modules informatiques'!$A$2:$D$50,4,FALSE()), "") | U33: =IFERROR(AVERAGE(C33:T33), "") -> 0 | V33: =IFERROR(VLOOKUP(V32,'Projets entreprise'!$C$2:$E$91,3,FALSE()), "") -> 0 | W33: =IFERROR(VLOOKUP(W32,'Projets entreprise'!$C$2:$E$91,3,FALSE()), "") -> 0 | X33: =IFERROR(VLOOKUP(X32,'Projets entreprise'!$C$2:$E$91,3,FALSE()), "") | Y33: =IFERROR(VLOOKUP(Y32,'Projets entreprise'!$C$2:$E$91,3,FALSE()), "") | Z33: =IFERROR(VLOOKUP(Z32,'Projets entreprise'!$C$2:$E$91,3,FALSE()), "") | AA33: =IFERROR(VLOOKUP(AA32,'Projets entreprise'!$C$2:$E$91,3,FALSE()), "") | AB33: =IFERROR(VLOOKUP(AB32,'Projets entreprise'!$C$2:$E$91,3,FALSE()), "") | AC33: =IFERROR(VLOOKUP(AC32,'Projets entreprise'!$C$2:$E$91,3,FALSE()), "") | ... AR33: =IFERROR(VLOOKUP(AR32,'Projets entreprise'!$C$2:$E$91,3,FALSE()), "") | AS33: =IFERROR(AVERAGE(V33:AR33), "") -> 0
A34: g2 | B34: Vérifier la faisabilité technique des prototypes d’interfaces utilisateur et les développer | C34: 322 | D34: 319 | E34: 320 | F34: 239 | M34: 294 | N34: 223 | O34: 335 | P34: 217 | V34: B20 | W34: B41 | X34: B51 | Y34: B52
C35: =IFERROR(VLOOKUP(C34,'Modules informatiques'!$A$2:$D$50,4,FALSE()), "") -> 0 | D35: =IFERROR(VLOOKUP(D34,'Modules informatiques'!$A$2:$D$50,4,FALSE()), "") -> 0 | E35: =IFERROR(VLOOKUP(E34,'Modules informatiques'!$A$2:$D$50,4,FALSE()), "") -> 0 | F35: =IFERROR(VLOOKUP(F34,'Modules informatiques'!$A$2:$D$50,4,FALSE()), "") | G35: =IFERROR(VLOOKUP(G34,'Modules informatiques'!$A$2:$D$50,4,FALSE()), "") | H35: =IFERROR(VLOOKUP(H34,'Modules informatiques'!$A$2:$D$50,4,FALSE()), "") | I35: =IFERROR(VLOOKUP(I34,'Modules informatiques'!$A$2:$D$50,4,FALSE()), "") | J35: =IFERROR(VLOOKUP(J34,'Modules informatiques'!$A$2:$D$50,4,FALSE()), "") | ... T35: =IFERROR(VLOOKUP(T34,'Modules informatiques'!$A$2:$D$50,4,FALSE()), "") | U35: =IFERROR(AVERAGE(C35:T35), "") -> 0 | V35: =IFERROR(VLOOKUP(V34,'Projets entreprise'!$C$2:$E$91,3,FALSE()), "") -> 0 | W35: =IFERROR(VLOOKUP(W34,'Projets entreprise'!$C$2:$E$91,3,FALSE()), "") -> 0 | X35: =IFERROR(VLOOKUP(X34,'Projets entreprise'!$C$2:$E$91,3,FALSE()), "") -> 0 | Y35: =IFERROR(VLOOKUP(Y34,'Projets entreprise'!$C$2:$E$91,3,FALSE()), "") -> 0 | Z35: =IFERROR(VLOOKUP(Z34,'Projets entreprise'!$C$2:$E$91,3,FALSE()), "") | AA35: =IFERROR(VLOOKUP(AA34,'Projets entreprise'!$C$2:$E$91,3,FALSE()), "") | AB35: =IFERROR(VLOOKUP(AB34,'Projets entreprise'!$C$2:$E$91,3,FALSE()), "") | AC35: =IFERROR(VLOOKUP(AC34,'Projets entreprise'!$C$2:$E$91,3,FALSE()), "") | ... AR35: =IFERROR(VLOOKUP(AR34,'Projets entreprise'!$C$2:$E$91,3,FALSE()), "") | AS35: =IFERROR(AVERAGE(V35:AR35), "") -> 0
A36: g3 | B36: Evaluer et documenter la sécurité des applications et des interfaces | C36: 183 | D36: 114 | E36: 450 | F36: 346 | M36: 295 | N36: 216 | O36: 217 | P36: 107 | V36: B51 | W36: B52
C37: =IFERROR(VLOOKUP(C36,'Modules informatiques'!$A$2:$D$50,4,FALSE()), "") -> 0 | D37: =IFERROR(VLOOKUP(D36,'Modules informatiques'!$A$2:$D$50,4,FALSE()), "") -> 0 | E37: =IFERROR(VLOOKUP(E36,'Modules informatiques'!$A$2:$D$50,4,FALSE()), "") -> 0 | F37: =IFERROR(VLOOKUP(F36,'Modules informatiques'!$A$2:$D$50,4,FALSE()), "") -> 0 | G37: =IFERROR(VLOOKUP(G36,'Modules informatiques'!$A$2:$D$50,4,FALSE()), "") | H37: =IFERROR(VLOOKUP(H36,'Modules informatiques'!$A$2:$D$50,4,FALSE()), "") | I37: =IFERROR(VLOOKUP(I36,'Modules informatiques'!$A$2:$D$50,4,FALSE()), "") | J37: =IFERROR(VLOOKUP(J36,'Modules informatiques'!$A$2:$D$50,4,FALSE()), "") | ... T37: =IFERROR(VLOOKUP(T36,'Modules informatiques'!$A$2:$D$50,4,FALSE()), "") | U37: =IFERROR(AVERAGE(C37:T37), "") -> 0 | V37: =IFERROR(VLOOKUP(V36,'Projets entreprise'!$C$2:$E$91,3,FALSE()), "") -> 0 | W37: =IFERROR(VLOOKUP(W36,'Projets entreprise'!$C$2:$E$91,3,FALSE()), "") -> 0 | X37: =IFERROR(VLOOKUP(X36,'Projets entreprise'!$C$2:$E$91,3,FALSE()), "") | Y37: =IFERROR(VLOOKUP(Y36,'Projets entreprise'!$C$2:$E$91,3,FALSE()), "") | Z37: =IFERROR(VLOOKUP(Z36,'Projets entreprise'!$C$2:$E$91,3,FALSE()), "") | AA37: =IFERROR(VLOOKUP(AA36,'Projets entreprise'!$C$2:$E$91,3,FALSE()), "") | AB37: =IFERROR(VLOOKUP(AB36,'Projets entreprise'!$C$2:$E$91,3,FALSE()), "") | AC37: =IFERROR(VLOOKUP(AC36,'Projets entreprise'!$C$2:$E$91,3,FALSE()), "") | ... AR37: =IFERROR(VLOOKUP(AR36,'Projets entreprise'!$C$2:$E$91,3,FALSE()), "") | AS37: =IFERROR(AVERAGE(V37:AR37), "") -> 0
A38: g4 | B38: Elaborer des variantes de mise en œuvre d’une application et développer la solution sur le plan conceptuel | C38: 319 | D38: 320 | E38: 323 | F38: 164 | G38: 321 | H38: 346 | I38: 306 | M38: 106 | N38: 223 | O38: 335 | P38: 259 | Q38: 216 | R38: 217 | S38: 210 | T38: 107 | V38: B42 | W38: B70
C39: =IFERROR(VLOOKUP(C38,'Modules informatiques'!$A$2:$D$50,4,FALSE()), "") -> 0 | D39: =IFERROR(VLOOKUP(D38,'Modules informatiques'!$A$2:$D$50,4,FALSE()), "") -> 0 | E39: =IFERROR(VLOOKUP(E38,'Modules informatiques'!$A$2:$D$50,4,FALSE()), "") -> 0 | F39: =IFERROR(VLOOKUP(F38,'Modules informatiques'!$A$2:$D$50,4,FALSE()), "") -> 0 | G39: =IFERROR(VLOOKUP(G38,'Modules informatiques'!$A$2:$D$50,4,FALSE()), "") -> 0 | H39: =IFERROR(VLOOKUP(H38,'Modules informatiques'!$A$2:$D$50,4,FALSE()), "") -> 0 | I39: =IFERROR(VLOOKUP(I38,'Modules informatiques'!$A$2:$D$50,4,FALSE()), "") -> 0 | J39: =IFERROR(VLOOKUP(J38,'Modules informatiques'!$A$2:$D$50,4,FALSE()), "") | ... T39: =IFERROR(VLOOKUP(T38,'Modules informatiques'!$A$2:$D$50,4,FALSE()), "") -> 0 | U39: =IFERROR(AVERAGE(C39:T39), "") -> 0 | V39: =IFERROR(VLOOKUP(V38,'Projets entreprise'!$C$2:$E$91,3,FALSE()), "") -> 0 | W39: =IFERROR(VLOOKUP(W38,'Projets entreprise'!$C$2:$E$91,3,FALSE()), "") -> 0 | X39: =IFERROR(VLOOKUP(X38,'Projets entreprise'!$C$2:$E$91,3,FALSE()), "") | Y39: =IFERROR(VLOOKUP(Y38,'Projets entreprise'!$C$2:$E$91,3,FALSE()), "") | Z39: =IFERROR(VLOOKUP(Z38,'Projets entreprise'!$C$2:$E$91,3,FALSE()), "") | AA39: =IFERROR(VLOOKUP(AA38,'Projets entreprise'!$C$2:$E$91,3,FALSE()), "") | AB39: =IFERROR(VLOOKUP(AB38,'Projets entreprise'!$C$2:$E$91,3,FALSE()), "") | AC39: =IFERROR(VLOOKUP(AC38,'Projets entreprise'!$C$2:$E$91,3,FALSE()), "") | ... AR39: =IFERROR(VLOOKUP(AR38,'Projets entreprise'!$C$2:$E$91,3,FALSE()), "") | AS39: =IFERROR(AVERAGE(V39:AR39), "") -> 0
A40: g5 | B40: Implémenter les applications et les interfaces selon le concept en respectant les exigences de sécurité | C40: 319 | D40: 320 | E40: 323 | F40: 293 | G40: 165 | H40: 321 | I40: 322 | J40: 183 | K40: 426 | L40: 324 | M40: 106 | N40: 294 | O40: 295 | P40: 223 | Q40: 335 | R40: 216 | S40: 217 | V40: B20 | W40: B41 | X40: B42 | Y40: B44 | Z40: E103 | AA40: B51 | AB40: B46 | AC40: E104 | AD40: B52 | AE40: B60 | AF40: B70 | AG40: E108
...
